Workbook

Sheet Taxonomy
A1: Cluster | B1: Editorial Role | C1: Item Status | D1: Verification Grade | E1: Rights Status | F1: Selflo Fit | G1: Source Type | H1: Quote Type | I1: Story Type | J1: Tradition / Region | K1: Release Readiness | L1: Lĩnh vực cuộc sống (Life Area) | M1: Chủ đề (Theme) | N1: Cảm xúc / trạng thái (Emotion / State) | O1: Hình thức nội dung (Content Form) | P1: Mức Coverage
A2: Exhaustion / Recovery / Work carryover | B2: Recognize | C2: Planned | D2: A - Primary source | E2: Public domain / likely | F2: High | G2: Primary text | H2: Verbatim | I2: Parable | J2: Taoism | K2: Not reviewed | L2: Nội tâm & hiểu mình | M2: Acceptance | N2: Mệt mỏi | O2: Quan sát trực tiếp | P2: Missing
A3: Self-compassion / Self-blame | B3: Name | C3: Collected | D3: B - Authoritative secondary | E3: Copyrighted / research only | F3: Medium | G3: Book | H3: Working translation | I3: Folktale | J3: Stoicism | K3: Research only | L3: Cảm xúc | M3: Agency | N3: Cạn năng lượng | O3: Ẩn dụ | P3: Thin
A4: Uncertainty / Choice / Agency | B4: Permit | C4: Needs Verification | D4: C - Plausible / needs primary | E4: Permission needed | F4: Low | G4: Speech | H4: Published translation | I4: Historical episode | J4: Early Buddhism | K4: Blocked - source | L4: Công việc & mục đích | M4: Attention | N4: Lo lắng | O4: Câu hỏi | P4: Covered
A5: Comparison / External standards / Values | B5: Reframe | C5: Verified | D5: D - Disputed / internet-only | E5: Selflo owned | F5: Not reviewed | G5: Letter | H5: Paraphrase | I5: Biography episode | J5: Greek philosophy | K5: Blocked - rights | L5: Quan hệ | M5: Boundaries | N5: Sợ hãi | O5: Nghịch lý | P5: Rich
A6: Attention / Noise / Deep focus | B6: Distinguish | C6: Needs Edit | D6: N/A - Selflo Original | E6: Unknown / verify | G6: Poem | H6: Proverb / traditional | I6: Research case | J6: Indian philosophy | K6: Blocked - story dependency | L6: Gia đình | M6: Change | N6: Bối rối | O6: Tục ngữ / ca dao / thành ngữ
A7: Learning / Failure / Quiet growth | B7: Return agency | C7: Shortlisted | G7: Proverb | H7: Selflo Original - AI-assisted draft | I7: Journalism case | J7: Vietnamese wisdom | K7: Needs owner review | L7: Lựa chọn & định hướng | M7: Choice | N7: Không chắc chắn | O7: Thơ / văn vần
A8: Change / Impermanence / Recovery | C8: Release | G8: Folk tradition | H8: Selflo Original - owner edited | I8: Documented personal account | J8: Chinese classics | K8: Ready candidate | L8: Học hỏi & phát triển | M8: Comparison | N8: Tội lỗi | O8: Đối thoại
A9: Mixed emotions / Emotional memory | C9: Hold | G9: Parable | I9: Literary episode | J9: Japanese wisdom / Zen | K9: Released | L9: Nghỉ ngơi & sức khỏe tinh thần | M9: Compassion | N9: Xấu hổ | O9: Trích đoạn triết học
A10: Meaning / Identity / Work | C10: Rejected | G10: Historical case | J10: Persian | L10: Ý nghĩa & bản sắc | M10: Control | N10: Tức giận | O10: Research-informed observation
A11: AI-age Human Judgment | G11: Biography | J11: Middle Eastern / Arabic | L11: Thay đổi / mất mát / chuyển tiếp | M11: Enoughness | N11: Buồn | O11: Story-derived insight
A12: Relationships / Boundaries / Connection | G12: Research paper | J12: African traditions | L12: Xã hội & văn hóa | M12: Failure | N12: Cô đơn | O12: Traditional wisdom
A13: Rest / Limits / Wellbeing | G13: Institutional source | J13: Jewish wisdom | L13: AI & tương lai | M13: Fear | N13: Trống rỗng | O13: Selflo Original
G14: Journalism | J14: European folk | M14: Grief | N14: Tê liệt
G15: Secondary scholarship | J15: World literature | M15: Identity | N15: Tiếc nuối
G16: Selflo Original | J16: Modern philosophy | M16: Impermanence | N16: Nhẹ nhõm
J17: Psychology | M17: Judgment | N17: Hy vọng
J18: Human sciences | M18: Meaning | N18: Biết ơn
J19: Modern work | M19: Patience | N19: Áp lực
J20: AI-era research | M20: Recovery | N20: Quá tải
J21: Other | M21: Responsibility | N21: Bình yên
M22: Rest | N22: Mixed / contradictory
M23: Self-worth | N23: Lingering emotion
M24: Simplicity | N24: Không gọi tên được
M25: Trust
M26: Uncertainty
M27: Values
M28: Connection
M29: Learning
M30: Hope
M31: Mortality

Sheet README
A1: SELFLO — Wisdom, Quote & Story Research Library
A3: Mục | B3: Giải thích | D3: V2 — CÁCH HIỂU TAXONOMY
A4: Mục tiêu | B4: Xây kho nguyên liệu lớn cho Selflo trước khi curate Release. Thu thập rộng, xác minh nguồn, chuẩn hóa, phân loại; KHÔNG mặc định nội dung thu thập sẽ được Release. | D4: Life Area | E4: Vùng đời sống rộng: Công việc, Quan hệ, Nội tâm...
A5: Pipeline | B5: Collect → Verify & Normalize → Classify → Selflo Fit Review → Release Curation → Story Selection/Adaptation. | D5: Human Experience | E5: Trải nghiệm cụ thể. Đây là đơn vị coverage chính.
A6: Ưu tiên nguồn | B6: Primary/authoritative source trước. Tránh Pinterest/quote-card/random quote aggregators nếu không truy được nguồn gốc. | D6: Theme | E6: Ý tưởng/khái niệm được content chạm tới.
A7: Quote hiện đại | B7: Đặc biệt kiểm tra fake attribution. Một câu hay nhưng nguồn yếu vẫn có thể giữ Research Pool với Verification C/D, không được tự động Release. | D7: Emotion / State | E7: Cảm xúc/trạng thái biên tập; không phải chẩn đoán.
A8: Selflo Original | B8: Chỉ tạo khi external source không phủ tốt. Phải ghi rõ Selflo Original / AI-assisted draft; không gán cho tác giả khác và không paraphrase để né copyright. | D8: Editorial Role | E8: Quote làm gì: nhận ra, gọi tên, cho phép, đổi góc nhìn, phân biệt, trả quyền lựa chọn.
A9: Story | B9: Chỉ lưu story/parables/historical/research/journalism có provenance rõ. Không tự bịa story để lấp coverage. | D9: Content Form | E9: Cách thể hiện: quan sát, ẩn dụ, câu hỏi, tục ngữ, thơ...
A10: Principle Library | B10: Lưu nguyên lý từ philosophy, psychology, human sciences và tài liệu AI. Principle là research seed; không mặc định là quote cho user. | D10: Principle | E10: Triết lý/research đứng phía sau.
A11: Coverage | B11: Theo dõi cả cluster và human experience. Mục tiêu 50 item/cluster là target research pool, không phải quota Release. | D11: Coverage | E11: Không phải chỉ đếm quote. Xem breadth + role diversity + source diversity + form diversity + quality.
A12: Editorial roles | B12: Recognize / Name / Permit / Reframe / Distinguish / Return agency. Một item có thể có Primary Role + Secondary Role.
A13: Verification | B13: A = primary source; B = authoritative secondary; C = plausible nhưng chưa có primary; D = disputed/internet-only; N/A = Selflo Original.
A14: Rights | B14: Tách quality khỏi rights. Nội dung copyrighted vẫn có thể lưu Research Pool nhưng phải đánh dấu research-only/permission needed.
A15: Cách dùng với AI | B15: Chọn một dòng trong 90-Day Plan, giao AI thực hiện theo AI Collection Guide, sau đó nhập kết quả vào Quote/Story/Principle/Source Library và cập nhật Actual.
A16: Quy tắc không bịa | B16: Nếu không tìm được source URL/work/chapter đáng tin: để trống hoặc đánh dấu Needs Verification. Không tự tạo URL, tác giả, tác phẩm, câu chuyện hay provenance.

Sheet 90-Day Plan
A1: Day | B1: Phase | C1: Collection Focus | D1: Primary Sources / Traditions | E1: What to Collect | F1: Quote Target | G1: Story Target | H1: Principle Target | I1: Quote Actual | J1: Story Actual | K1: Principle Actual | L1: Status | M1: Progress % | N1: Notes
A2: 1 | B2: A. Ancient Foundations | C2: Laozi I | D2: Tao Te Ching ch. 1–20 | E2: Passages on opposites, desire, knowing, simplicity; original Chinese + chapter + working VI | F2: 20 | G2: 1 | H2: 4 | I2: 63 | J2: 0 | K2: 10 | L2: Done | M2: =1 | N2: FULL SCOPE AUDIT complete. 63 candidate passages; 0 true stories; 10 principle seeds. Original Classical Chinese retained; Vietnamese is working translation.
A3: 2 | B3: A. Ancient Foundations | C3: Laozi II | D3: Tao Te Ching ch. 21–50 | E3: Non-action, softness, enoughness, humility, change | F3: 20 | G3: 1 | H3: 4 | I3: 118 | J3: 0 | K3: 12 | L3: Done | M3: 1 | N3: FULL SCOPE AUDIT complete for Laozi chapters 21–50. 118 candidates; 0 true stories; 12 principle seeds. Original Chinese retained; Vietnamese is working translation.
A4: 3 | B4: A. Ancient Foundations | C4: Laozi III | D4: Tao Te Ching ch. 51–81 | E4: Loss/gain, control, contentment, strength/softness; deduplicate Laozi | F4: 20 | G4: 1 | H4: 4 | L4: Planned | M4: =IFERROR((I4+J4+K4)/(F4+G4+H4),0)
A5: 4 | B5: A. Ancient Foundations | C5: Zhuangzi | D5: Zhuangzi primary text | E5: Passages + parables: Butterfly Dream, Empty Boat, Useless Tree, Cook Ding, etc. | F5: 20 | G5: 7 | H5: 5 | L5: Planned | M5: =IFERROR((I5+J5+K5)/(F5+G5+H5),0)
A6: 5 | B6: A. Ancient Foundations | C6: Liezi | D6: Liezi | E6: Passages + traceable stories | F6: 20 | G6: 4 | H6: 4 | L6: Planned | M6: =IFERROR((I6+J6+K6)/(F6+G6+H6),0)
A7: 6 | B7: A. Ancient Foundations | C7: Huainanzi | D7: Huainanzi | E7: Passages + parables including Sai Weng; change/judgment/fortune | F7: 20 | G7: 5 | H7: 4 | L7: Planned | M7: =IFERROR((I7+J7+K7)/(F7+G7+H7),0)
A8: 7 | B8: A. Ancient Foundations | C8: Epictetus | D8: Enchiridion / Discourses | E8: Control, judgment, desire, externals, agency | F8: 22 | G8: 2 | H8: 4 | L8: Planned | M8: =IFERROR((I8+J8+K8)/(F8+G8+H8),0)
A9: 8 | B9: A. Ancient Foundations | C9: Marcus Aurelius | D9: Meditations | E9: Time, judgment, change, mortality, social life | F9: 22 | G9: 1 | H9: 4 | L9: Planned | M9: =IFERROR((I9+J9+K9)/(F9+G9+H9),0)
A10: 9 | B10: A. Ancient Foundations | C10: Seneca | D10: Letters / Essays | E10: Time, adversity, wealth, anger, friendship, mortality | F10: 22 | G10: 2 | H10: 4 | L10: Planned | M10: =IFERROR((I10+J10+K10)/(F10+G10+H10),0)
A11: 10 | B11: A. Ancient Foundations | C11: Musonius Rufus + Stoic fragments | D11: Lectures / fragments | E11: Practice, simplicity, character; disputed attribution review | F11: 18 | G11: 1 | H11: 3 | L11: Planned | M11: =IFERROR((I11+J11+K11)/(F11+G11+H11),0)
A12: 11 | B12: A. Ancient Foundations | C12: Dhammapada | D12: Dhammapada | E12: Mind, attention, impermanence, conduct, suffering | F12: 22 | G12: 1 | H12: 4 | L12: Planned | M12: =IFERROR((I12+J12+K12)/(F12+G12+H12),0)
A13: 12 | B13: A. Ancient Foundations | C13: Majjhima Nikaya | D13: Selected suttas | E13: Passages + metaphors/parables such as raft where sourced | F13: 18 | G13: 4 | H13: 4 | L13: Planned | M13: =IFERROR((I13+J13+K13)/(F13+G13+H13),0)
A14: 13 | B14: A. Ancient Foundations | C14: Samyutta / Anguttara Nikaya | D14: Selected suttas | E14: Impermanence, attachment, perception, compassion, attention | F14: 20 | G14: 3 | H14: 4 | L14: Planned | M14: =IFERROR((I14+J14+K14)/(F14+G14+H14),0)
A15: 14 | B15: A. Ancient Foundations | C15: Early Buddhist parables | D15: Early canonical / reputable collections | E15: Traceable parables and metaphors; provenance first | F15: 16 | G15: 7 | H15: 4 | L15: Planned | M15: =IFERROR((I15+J15+K15)/(F15+G15+H15),0)
... A91: 90 | B91: F. Coverage Gap Filling | C91: Mixed emotions / Emotional memory + final audit | D91: Whole collected library + targeted authoritative sources | E91: Fill under-covered human experiences only; prefer sources/traditions not yet overrepresented; final day produces coverage audit | F91: 20 | G91: 3 | H91: 4 | L91: Planned | M91: =IFERROR((I91+J91+K91)/(F91+G91+H91),0)

Sheet Quote Library
A1: Quote ID | B1: Status | C1: Cluster Primary | D1: Cluster Secondary | E1: Human Experience | F1: Editorial Role Primary | G1: Editorial Role Secondary | H1: Quote Text - Original | I1: Language | J1: Quote Text - Working VI | K1: Author / Attribution | L1: Tradition / Region | M1: Source Title | N1: Work / Chapter / Location | O1: Source URL | P1: Source Type | Q1: Quote Type | R1: Verification Grade | S1: Verification Notes | T1: Rights Status | U1: Copyright / Usage Notes | V1: Selflo Fit | W1: Selflo Fit Notes | X1: Directive Risk | Y1: Overlap / Duplicate Risk | Z1: Related Principle ID(s) | AA1: Related Story ID(s) | AB1: Story Dependency Gate | AC1: Owner Review | AD1: Release Readiness | AE1: Current Library Location | AF1: Collected Day | AG1: Collected By | AH1: Date Collected | AI1: Notes

Sheet Story Library
A1: Story ID | B1: Status | C1: Title | D1: Original / Local Title | E1: Story Type | F1: Tradition / Region | G1: Cluster Primary | H1: Cluster Secondary | I1: Human Experience | J1: Summary (research only) | K1: Primary Source / Work | L1: Source Location | M1: Source URL | N1: Secondary Verification URL | O1: Verification Grade | P1: Verification Notes | Q1: Rights Status | R1: Copyright / Adaptation Notes | S1: Historical / Traditional Context | T1: Key Principle ID(s) | U1: Related Quote ID(s) | V1: Selflo Fit | W1: Selflo Fit Notes | X1: Adaptation Allowed? | Y1: Human Edited? | Z1: Rights Verified? | AA1: Story Gate Status | AB1: Current Library Location | AC1: Collected Day | AD1: Collected By | AE1: Date Collected | AF1: Notes

Sheet Principle Library
A1: Principle ID | B1: Status | C1: Principle Name | D1: Domain | E1: Definition / Claim | F1: Source Title | G1: Source Author / Institution | H1: Source URL | I1: Source Type | J1: Evidence / Basis | K1: Limitations / Counterpoints | L1: Verification Grade | M1: Related AI-doc Principle | N1: Human Experience Link | O1: Cluster Primary | P1: Editorial Relevance | Q1: Related Quote ID(s) | R1: Related Story ID(s) | S1: Selflo Use | T1: Selflo Original Seed Allowed? | U1: Collected Day | V1: Notes
A2: principle.laozi.naming_not_reality | B2: Collected | C2: Tên gọi không phải toàn bộ thực tại | D2: Philosophy / judgment | E2: Một nhãn hoặc mô tả giúp ta thấy một khía cạnh nhưng không đồng nhất với toàn bộ điều được mô tả. | F2: 道德經 / Tao Te Ching | G2: Laozi / 老子 | H2: https://zh.wikisource.org/zh-hans/%E9%81%93%E5%BE%B7%E7%B6%93_(%E7%8E%8B%E5%BC%BC%E6%9C%AC) | I2: Primary text | J2: Ch.1: distinction between what can be named/spoken and the enduring Dao. | K2: Không biến thành chủ nghĩa tương đối. | L2: A - Primary source | M2: Human judgment | N2: Tên gọi không chứa trọn trải nghiệm | O2: AI-age Human Judgment | P2: Distinguish | Q2: research.laozi.ch01.001 | S2: Editorial lens | T2: Yes | U2: 1 | V2: Day 1 seed.
A3: principle.laozi.relational_opposites | B3: Collected | C3: Các đối cực làm rõ lẫn nhau | D3: Philosophy | E3: Một số khái niệm trở nên rõ trong quan hệ/đối chiếu với phía kia. | F3: 道德經 / Tao Te Ching | G3: Laozi / 老子 | H3: https://zh.wikisource.org/zh-hans/%E9%81%93%E5%BE%B7%E7%B6%93_(%E7%8E%8B%E5%BC%BC%E6%9C%AC) | I3: Primary text | J3: Ch.2 relational pairs. | K3: Không suy rộng thành mọi đối lập đều tốt. | L3: A - Primary source | M3: Interdependence | N3: Hai mặt cùng tồn tại | O3: Mixed emotions / Emotional memory | P3: Distinguish | Q3: research.laozi.ch02.006 | S3: Editorial lens | T3: Yes | U3: 1 | V3: Day 1 seed.
A4: principle.laozi.non_attachment_to_achievement | B4: Collected | C4: Thành tựu không cần trở thành bản sắc | D4: Philosophy / work | E4: Làm xong một việc không nhất thiết phải bám vào công trạng hay biến thành tự định nghĩa. | F4: 道德經 / Tao Te Ching | G4: Laozi / 老子 | H4: https://zh.wikisource.org/zh-hans/%E9%81%93%E5%BE%B7%E7%B6%93_(%E7%8E%8B%E5%BC%BC%E6%9C%AC) | I4: Primary text | J4: Ch.2 and Ch.9. | K4: Không phủ nhận thành tựu/trách nhiệm. | L4: A - Primary source | M4: Identity in abundance | N4: Thành tựu và bản sắc | O4: Meaning / Identity / Work | P4: Distinguish | Q4: research.laozi.ch02.008; research.laozi.ch09.026 | S4: Editorial lens | T4: Yes | U4: 1 | V4: Day 1 seed.
A5: principle.laozi.functional_emptiness | B5: Collected | C5: Khoảng trống có chức năng | D5: Philosophy / attention | E5: Giá trị không chỉ đến từ thứ được thêm vào; khoảng trống có thể là điều kiện để một vật hay trải nghiệm có công dụng. | F5: 道德經 / Tao Te Ching | G5: Laozi / 老子 | H5: https://zh.wikisource.org/zh-hans/%E9%81%93%E5%BE%B7%E7%B6%93_(%E7%8E%8B%E5%BC%BC%E6%9C%AC) | I5: Primary text | J5: Ch.11 wheel, vessel, room. | K5: Không biến thành 'ít luôn tốt hơn'. | L5: A - Primary source | M5: Attention scarcity | N5: Quá nhiều đầu vào, thiếu khoảng trống | O5: Attention / Noise / Deep focus | P5: Reframe | Q5: research.laozi.ch11.* | S5: Product philosophy | T5: Yes | U5: 1 | V5: Core Selflo/AI-age principle.
A6: principle.laozi.enoughness_limits | B6: Collected | C6: Biết đủ và giới hạn | D6: Philosophy / wellbeing | E6: Tiếp tục làm đầy hoặc tối ưu không phải lúc nào cũng tạo thêm giá trị; có ngưỡng làm giảm tính bền vững. | F6: 道德經 / Tao Te Ching | G6: Laozi / 老子 | H6: https://zh.wikisource.org/zh-hans/%E9%81%93%E5%BE%B7%E7%B6%93_(%E7%8E%8B%E5%BC%BC%E6%9C%AC) | I6: Primary text | J6: Ch.9 and Ch.15. | K6: Không dùng để chống tham vọng. | L6: A - Primary source | M6: Productivity ≠ leisure | N6: Cạn năng lượng / over-optimization | O6: Rest / Limits / Wellbeing | P6: Distinguish | Q6: research.laozi.ch09.*; research.laozi.ch15.* | S6: Editorial lens | T6: Yes | U6: 1 | V6: Day 1 seed.
A7: principle.laozi.stimulus_overload | B7: Collected | C7: Quá nhiều kích thích có thể làm giảm khả năng cảm nhận | D7: Philosophy / attention | E7: Khi đầu vào tăng quá mức, khả năng phân biệt và chú ý có thể giảm thay vì tăng. | F7: 道德經 / Tao Te Ching | G7: Laozi / 老子 | H7: https://zh.wikisource.org/zh-hans/%E9%81%93%E5%BE%B7%E7%B6%93_(%E7%8E%8B%E5%BC%BC%E6%9C%AC) | I7: Primary text | J7: Ch.12. | K7: Đây là ẩn dụ triết học cổ, không phải bằng chứng khoa học hiện đại. | L7: A - Primary source | M7: Information abundance / noise | N7: Quá tải thông tin | O7: Attention / Noise / Deep focus | P7: Recognize | Q7: research.laozi.ch12.* | S7: Quote seed | T7: Yes | U7: 1 | V7: Connect to modern research later.
A8: principle.laozi.clarity_not_forced | B8: Collected | C8: Sáng rõ không phải lúc nào cũng cần bị ép ra ngay | D8: Philosophy / reflection | E8: Khi trải nghiệm còn đục/rối, không tiếp tục khuấy động có thể tạo điều kiện cho sáng rõ xuất hiện dần. | F8: 道德經 / Tao Te Ching | G8: Laozi / 老子 | H8: https://zh.wikisource.org/zh-hans/%E9%81%93%E5%BE%B7%E7%B6%93_(%E7%8E%8B%E5%BC%BC%E6%9C%AC) | I8: Primary text | J8: Ch.15 muddy water. | K8: Không hứa chờ đợi sẽ tự giải quyết vấn đề. | L8: A - Primary source | M8: Fast execution / slow cognition | N8: Chưa gọi tên được / chưa rõ lựa chọn | O8: Uncertainty / Choice / Agency | P8: Permit | Q8: research.laozi.ch15.* | S8: Editorial lens | T8: Yes | U8: 1 | V8: Strong Selflo principle.
A9: principle.laozi.enduring_principles | B9: Collected | C9: Nguyên lý bền để soi hoàn cảnh mới | D9: Philosophy / judgment | E9: Một số nguyên lý có thể tồn tại lâu hơn bối cảnh cụ thể và giúp soi tình huống mới. | F9: 道德經 / Tao Te Ching | G9: Laozi / 老子 | H9: https://zh.wikisource.org/zh-hans/%E9%81%93%E5%BE%B7%E7%B6%93_(%E7%8E%8B%E5%BC%BC%E6%9C%AC) | I9: Primary text | J9: Ch.14 and Ch.16. | K9: Không giả định mọi nguyên lý cổ đều đúng cho hiện đại. | L9: A - Primary source | M9: Enduring principles | N9: Bối cảnh AI thay đổi nhanh | O9: AI-age Human Judgment | P9: Distinguish | Q9: research.laozi.ch14.*; research.laozi.ch16.* | S9: Product philosophy | T9: Yes | U9: 1 | V9: Directly relevant to AI-era docs.
A10: principle.laozi.return_agency | B10: Collected | C10: Hỗ trợ tốt có thể giữ lại cảm giác chủ thể | D10: Philosophy / leadership | E10: Một dạng hỗ trợ tốt không nhất thiết khiến người nhận cảm thấy bị điều khiển; họ vẫn thấy mình là người thực hiện. | F10: 道德經 / Tao Te Ching | G10: Laozi / 老子 | H10: https://zh.wikisource.org/zh-hans/%E9%81%93%E5%BE%B7%E7%B6%93_(%E7%8E%8B%E5%BC%BC%E6%9C%AC) | I10: Primary text | J10: Ch.17. | K10: Đây là diễn giải editorial, không phải kết luận duy nhất. | L10: A - Primary source | M10: Human agency | N10: Người dùng vẫn là chủ thể | O10: AI-age Human Judgment | P10: Return agency | Q10: research.laozi.ch17.* | S10: Product philosophy | T10: Yes | U10: 1 | V10: Core Selflo philosophy.
A11: principle.laozi.social_comparison_uncertainty | B11: Collected | C11: Sự chắc chắn của số đông không quyết định trải nghiệm của mình | D11: Philosophy / self-understanding | E11: Cảm giác người khác đều đủ, rõ và có hướng đi có thể cùng tồn tại với việc mình chưa rõ. | F11: 道德經 / Tao Te Ching | G11: Laozi / 老子 | H11: https://zh.wikisource.org/zh-hans/%E9%81%93%E5%BE%B7%E7%B6%93_(%E7%8E%8B%E5%BC%BC%E6%9C%AC) | I11: Primary text | J11: Ch.20. | K11: Không lãng mạn hóa cô lập hoặc khác biệt. | L11: A - Primary source | M11: Human judgment | N11: Mọi người có vẻ biết còn mình chưa biết | O11: Comparison / External standards / Values | P11: Recognize | Q11: research.laozi.ch20.* | S11: Editorial lens | T11: Yes | U11: 1 | V11: Strong recognition/permission seed.
A302: principle.laozi.day2.progress_can_look_backward | H302: https://zh.wikisource.org/zh-hant/%E9%81%93%E5%BE%B7%E7%B6%93_%28%E7%8E%8B%E5%BC%BC%E6%9C%AC%29
A303: principle.laozi.day2.soft_strength | H303: https://zh.wikisource.org/zh-hant/%E9%81%93%E5%BE%B7%E7%B6%93_%28%E7%8E%8B%E5%BC%BC%E6%9C%AC%29
A304: principle.laozi.day2.self_knowledge | H304: https://zh.wikisource.org/zh-hant/%E9%81%93%E5%BE%B7%E7%B6%93_%28%E7%8E%8B%E5%BC%BC%E6%9C%AC%29
A305: principle.laozi.day2.enough_and_stop | H305: https://zh.wikisource.org/zh-hant/%E9%81%93%E5%BE%B7%E7%B6%93_%28%E7%8E%8B%E5%BC%BC%E6%9C%AC%29
A306: principle.laozi.day2.context_over_force | H306: https://zh.wikisource.org/zh-hant/%E9%81%93%E5%BE%B7%E7%B6%93_%28%E7%8E%8B%E5%BC%BC%E6%9C%AC%29
A307: principle.laozi.day2.value_not_attention | H307: https://zh.wikisource.org/zh-hant/%E9%81%93%E5%BE%B7%E7%B6%93_%28%E7%8E%8B%E5%BC%BC%E6%9C%AC%29
A308: principle.laozi.day2.whole_not_parts | H308: https://zh.wikisource.org/zh-hant/%E9%81%93%E5%BE%B7%E7%B6%93_%28%E7%8E%8B%E5%BC%BC%E6%9C%AC%29
A309: principle.laozi.day2.addition_and_subtraction | H309: https://zh.wikisource.org/zh-hant/%E9%81%93%E5%BE%B7%E7%B6%93_%28%E7%8E%8B%E5%BC%BC%E6%9C%AC%29
A310: principle.laozi.day2.nonfixed_response | H310: https://zh.wikisource.org/zh-hant/%E9%81%93%E5%BE%B7%E7%B6%93_%28%E7%8E%8B%E5%BC%BC%E6%9C%AC%29
A311: principle.laozi.day2.return_agency | H311: https://zh.wikisource.org/zh-hant/%E9%81%93%E5%BE%B7%E7%B6%93_%28%E7%8E%8B%E5%BC%BC%E6%9C%AC%29
A312: principle.laozi.day2.form_not_substance | H312: https://zh.wikisource.org/zh-hant/%E9%81%93%E5%BE%B7%E7%B6%93_%28%E7%8E%8B%E5%BC%BC%E6%9C%AC%29
A313: principle.laozi.day2.human_judgment_limits | H313: https://zh.wikisource.org/zh-hant/%E9%81%93%E5%BE%B7%E7%B6%93_%28%E7%8E%8B%E5%BC%BC%E6%9C%AC%29

Sheet Source Registry
A1: Source ID | B1: Author / Tradition | C1: Culture / Region | D1: Source Title | E1: Source Type | F1: Original Language | G1: Approx. Date / Era | H1: Primary URL | I1: Secondary Verification URL | J1: Reliability Tier | K1: Public Domain? | L1: Rights Notes | M1: Used for Quote IDs | N1: Used for Story IDs | O1: Used for Principle IDs | P1: First Collected Day | Q1: Verification Notes
A2: SRC-LAOZI-WB | B2: Laozi / 王弼 recension | C2: China | D2: 道德經 (王弼本) | E2: Primary text | F2: Classical Chinese | G2: Ancient text; Wang Bi commentary 3rd c. CE | H2: https://zh.wikisource.org/zh-hans/%E9%81%93%E5%BE%B7%E7%B6%93_(%E7%8E%8B%E5%BC%BC%E6%9C%AC) | I2: https://ctext.org/dao-de-jing/zh | J2: Tier 1 - Primary/Institutional | K2: Yes | L2: Ancient source text; verify edition choice for scholarly publication. | M2: Day 1 Laozi ch.1–20 | O2: principle.laozi.* | P2: 1 | Q2: Primary Chinese text used for exact original wording.
A3: SRC-CTEXT-LAOZI | B3: Laozi / Chinese Text Project | C3: China | D3: Dao De Jing | E3: Institutional source | F3: Classical Chinese / English | G3: Digital scholarly corpus | H3: https://ctext.org/dao-de-jing/zh | I3: https://zh.wikisource.org/zh-hans/%E9%81%93%E5%BE%B7%E7%B6%93_(%E7%8E%8B%E5%BC%BC%E6%9C%AC) | J3: Tier 1 - Primary/Institutional | K3: Yes | L3: Cross-check source. | M3: Day 1 cross-check | O3: principle.laozi.* | P3: 1 | Q3: Chinese text + Legge translation cross-check.
A4: SRC-LEGGE-1891 | B4: Laozi; trans. James Legge | C4: UK / China | D4: The Tao Teh King, or the Tao and its Characteristics | E4: Book | F4: English | G4: 1891 | H4: https://www.gutenberg.org/ebooks/216 | I4: https://ctext.org/dao-de-jing/zh | J4: Tier 2 - Scholarly/Authoritative | K4: Yes | L4: Project Gutenberg marks this edition public domain in the USA. | M4: Translation comparison | O4: principle.laozi.* | P4: 1 | Q4: Public-domain English comparison; not used as Vietnamese text.

Sheet Coverage Map
A1: SELFLO COVERAGE MAP — Research Pool
A3: Cluster | B3: Target Pool | C3: Quote Count | D3: Story Count | E3: Principle Count | F3: Verified A/B Quotes | G3: High Selflo Fit | H3: Released Quotes | I3: Gap | J3: Coverage % | K3: Priority | L3: Notes
A4: Exhaustion / Recovery / Work carryover | B4: 50 | C4: =COUNTIF('Quote Library'!$C$2:$C$500,A4)+COUNTIF('Quote Library'!$D$2:$D$500,A4) | D4: =COUNTIF('Story Library'!$G$2:$G$300,A4)+COUNTIF('Story Library'!$H$2:$H$300,A4) | E4: =COUNTIF('Principle Library'!$O$2:$O$300,A4) | F4: =COUNTIFS('Quote Library'!$C$2:$C$500,A4,'Quote Library'!$R$2:$R$500,"A - Primary source")+COUNTIFS('Quote Library'!$C$2:$C$500,A4,'Quote Library'!$R$2:$R$500,"B - Authoritative secondary") | G4: =COUNTIFS('Quote Library'!$C$2:$C$500,A4,'Quote Library'!$V$2:$V$500,"High") | H4: =COUNTIFS('Quote Library'!$C$2:$C$500,A4,'Quote Library'!$AD$2:$AD$500,"Released") | I4: =MAX(B4-C4,0) | J4: =MIN(C4/B4,1) | K4: =IF(J4<0.5,"High",IF(J4<0.9,"Medium","Filled"))
A5: Self-compassion / Self-blame | B5: 50 | C5: =COUNTIF('Quote Library'!$C$2:$C$500,A5)+COUNTIF('Quote Library'!$D$2:$D$500,A5) | D5: =COUNTIF('Story Library'!$G$2:$G$300,A5)+COUNTIF('Story Library'!$H$2:$H$300,A5) | E5: =COUNTIF('Principle Library'!$O$2:$O$300,A5) | F5: =COUNTIFS('Quote Library'!$C$2:$C$500,A5,'Quote Library'!$R$2:$R$500,"A - Primary source")+COUNTIFS('Quote Library'!$C$2:$C$500,A5,'Quote Library'!$R$2:$R$500,"B - Authoritative secondary") | G5: =COUNTIFS('Quote Library'!$C$2:$C$500,A5,'Quote Library'!$V$2:$V$500,"High") | H5: =COUNTIFS('Quote Library'!$C$2:$C$500,A5,'Quote Library'!$AD$2:$AD$500,"Released") | I5: =MAX(B5-C5,0) | J5: =MIN(C5/B5,1) | K5: =IF(J5<0.5,"High",IF(J5<0.9,"Medium","Filled"))
A6: Uncertainty / Choice / Agency | B6: 50 | C6: =COUNTIF('Quote Library'!$C$2:$C$500,A6)+COUNTIF('Quote Library'!$D$2:$D$500,A6) | D6: =COUNTIF('Story Library'!$G$2:$G$300,A6)+COUNTIF('Story Library'!$H$2:$H$300,A6) | E6: =COUNTIF('Principle Library'!$O$2:$O$300,A6) | F6: =COUNTIFS('Quote Library'!$C$2:$C$500,A6,'Quote Library'!$R$2:$R$500,"A - Primary source")+COUNTIFS('Quote Library'!$C$2:$C$500,A6,'Quote Library'!$R$2:$R$500,"B - Authoritative secondary") | G6: =COUNTIFS('Quote Library'!$C$2:$C$500,A6,'Quote Library'!$V$2:$V$500,"High") | H6: =COUNTIFS('Quote Library'!$C$2:$C$500,A6,'Quote Library'!$AD$2:$AD$500,"Released") | I6: =MAX(B6-C6,0) | J6: =MIN(C6/B6,1) | K6: =IF(J6<0.5,"High",IF(J6<0.9,"Medium","Filled"))
A7: Comparison / External standards / Values | B7: 50 | C7: =COUNTIF('Quote Library'!$C$2:$C$500,A7)+COUNTIF('Quote Library'!$D$2:$D$500,A7) | D7: =COUNTIF('Story Library'!$G$2:$G$300,A7)+COUNTIF('Story Library'!$H$2:$H$300,A7) | E7: =COUNTIF('Principle Library'!$O$2:$O$300,A7) | F7: =COUNTIFS('Quote Library'!$C$2:$C$500,A7,'Quote Library'!$R$2:$R$500,"A - Primary source")+COUNTIFS('Quote Library'!$C$2:$C$500,A7,'Quote Library'!$R$2:$R$500,"B - Authoritative secondary") | G7: =COUNTIFS('Quote Library'!$C$2:$C$500,A7,'Quote Library'!$V$2:$V$500,"High") | H7: =COUNTIFS('Quote Library'!$C$2:$C$500,A7,'Quote Library'!$AD$2:$AD$500,"Released") | I7: =MAX(B7-C7,0) | J7: =MIN(C7/B7,1) | K7: =IF(J7<0.5,"High",IF(J7<0.9,"Medium","Filled"))
A8: Attention / Noise / Deep focus | B8: 50 | C8: =COUNTIF('Quote Library'!$C$2:$C$500,A8)+COUNTIF('Quote Library'!$D$2:$D$500,A8) | D8: =COUNTIF('Story Library'!$G$2:$G$300,A8)+COUNTIF('Story Library'!$H$2:$H$300,A8) | E8: =COUNTIF('Principle Library'!$O$2:$O$300,A8) | F8: =COUNTIFS('Quote Library'!$C$2:$C$500,A8,'Quote Library'!$R$2:$R$500,"A - Primary source")+COUNTIFS('Quote Library'!$C$2:$C$500,A8,'Quote Library'!$R$2:$R$500,"B - Authoritative secondary") | G8: =COUNTIFS('Quote Library'!$C$2:$C$500,A8,'Quote Library'!$V$2:$V$500,"High") | H8: =COUNTIFS('Quote Library'!$C$2:$C$500,A8,'Quote Library'!$AD$2:$AD$500,"Released") | I8: =MAX(B8-C8,0) | J8: =MIN(C8/B8,1) | K8: =IF(J8<0.5,"High",IF(J8<0.9,"Medium","Filled"))
A9: Learning / Failure / Quiet growth | B9: 50 | C9: =COUNTIF('Quote Library'!$C$2:$C$500,A9)+COUNTIF('Quote Library'!$D$2:$D$500,A9) | D9: =COUNTIF('Story Library'!$G$2:$G$300,A9)+COUNTIF('Story Library'!$H$2:$H$300,A9) | E9: =COUNTIF('Principle Library'!$O$2:$O$300,A9) | F9: =COUNTIFS('Quote Library'!$C$2:$C$500,A9,'Quote Library'!$R$2:$R$500,"A - Primary source")+COUNTIFS('Quote Library'!$C$2:$C$500,A9,'Quote Library'!$R$2:$R$500,"B - Authoritative secondary") | G9: =COUNTIFS('Quote Library'!$C$2:$C$500,A9,'Quote Library'!$V$2:$V$500,"High") | H9: =COUNTIFS('Quote Library'!$C$2:$C$500,A9,'Quote Library'!$AD$2:$AD$500,"Released") | I9: =MAX(B9-C9,0) | J9: =MIN(C9/B9,1) | K9: =IF(J9<0.5,"High",IF(J9<0.9,"Medium","Filled"))
A10: Change / Impermanence / Recovery | B10: 50 | C10: =COUNTIF('Quote Library'!$C$2:$C$500,A10)+COUNTIF('Quote Library'!$D$2:$D$500,A10) | D10: =COUNTIF('Story Library'!$G$2:$G$300,A10)+COUNTIF('Story Library'!$H$2:$H$300,A10) | E10: =COUNTIF('Principle Library'!$O$2:$O$300,A10) | F10: =COUNTIFS('Quote Library'!$C$2:$C$500,A10,'Quote Library'!$R$2:$R$500,"A - Primary source")+COUNTIFS('Quote Library'!$C$2:$C$500,A10,'Quote Library'!$R$2:$R$500,"B - Authoritative secondary") | G10: =COUNTIFS('Quote Library'!$C$2:$C$500,A10,'Quote Library'!$V$2:$V$500,"High") | H10: =COUNTIFS('Quote Library'!$C$2:$C$500,A10,'Quote Library'!$AD$2:$AD$500,"Released") | I10: =MAX(B10-C10,0) | J10: =MIN(C10/B10,1) | K10: =IF(J10<0.5,"High",IF(J10<0.9,"Medium","Filled"))
A11: Mixed emotions / Emotional memory | B11: 50 | C11: =COUNTIF('Quote Library'!$C$2:$C$500,A11)+COUNTIF('Quote Library'!$D$2:$D$500,A11) | D11: =COUNTIF('Story Library'!$G$2:$G$300,A11)+COUNTIF('Story Library'!$H$2:$H$300,A11) | E11: =COUNTIF('Principle Library'!$O$2:$O$300,A11) | F11: =COUNTIFS('Quote Library'!$C$2:$C$500,A11,'Quote Library'!$R$2:$R$500,"A - Primary source")+COUNTIFS('Quote Library'!$C$2:$C$500,A11,'Quote Library'!$R$2:$R$500,"B - Authoritative secondary") | G11: =COUNTIFS('Quote Library'!$C$2:$C$500,A11,'Quote Library'!$V$2:$V$500,"High") | H11: =COUNTIFS('Quote Library'!$C$2:$C$500,A11,'Quote Library'!$AD$2:$AD$500,"Released") | I11: =MAX(B11-C11,0) | J11: =MIN(C11/B11,1) | K11: =IF(J11<0.5,"High",IF(J11<0.9,"Medium","Filled"))
A12: Meaning / Identity / Work | B12: 50 | C12: =COUNTIF('Quote Library'!$C$2:$C$500,A12)+COUNTIF('Quote Library'!$D$2:$D$500,A12) | D12: =COUNTIF('Story Library'!$G$2:$G$300,A12)+COUNTIF('Story Library'!$H$2:$H$300,A12) | E12: =COUNTIF('Principle Library'!$O$2:$O$300,A12) | F12: =COUNTIFS('Quote Library'!$C$2:$C$500,A12,'Quote Library'!$R$2:$R$500,"A - Primary source")+COUNTIFS('Quote Library'!$C$2:$C$500,A12,'Quote Library'!$R$2:$R$500,"B - Authoritative secondary") | G12: =COUNTIFS('Quote Library'!$C$2:$C$500,A12,'Quote Library'!$V$2:$V$500,"High") | H12: =COUNTIFS('Quote Library'!$C$2:$C$500,A12,'Quote Library'!$AD$2:$AD$500,"Released") | I12: =MAX(B12-C12,0) | J12: =MIN(C12/B12,1) | K12: =IF(J12<0.5,"High",IF(J12<0.9,"Medium","Filled"))
A13: AI-age Human Judgment | B13: 50 | C13: =COUNTIF('Quote Library'!$C$2:$C$500,A13)+COUNTIF('Quote Library'!$D$2:$D$500,A13) | D13: =COUNTIF('Story Library'!$G$2:$G$300,A13)+COUNTIF('Story Library'!$H$2:$H$300,A13) | E13: =COUNTIF('Principle Library'!$O$2:$O$300,A13) | F13: =COUNTIFS('Quote Library'!$C$2:$C$500,A13,'Quote Library'!$R$2:$R$500,"A - Primary source")+COUNTIFS('Quote Library'!$C$2:$C$500,A13,'Quote Library'!$R$2:$R$500,"B - Authoritative secondary") | G13: =COUNTIFS('Quote Library'!$C$2:$C$500,A13,'Quote Library'!$V$2:$V$500,"High") | H13: =COUNTIFS('Quote Library'!$C$2:$C$500,A13,'Quote Library'!$AD$2:$AD$500,"Released") | I13: =MAX(B13-C13,0) | J13: =MIN(C13/B13,1) | K13: =IF(J13<0.5,"High",IF(J13<0.9,"Medium","Filled"))
A14: Relationships / Boundaries / Connection | B14: 50 | C14: =COUNTIF('Quote Library'!$C$2:$C$500,A14)+COUNTIF('Quote Library'!$D$2:$D$500,A14) | D14: =COUNTIF('Story Library'!$G$2:$G$300,A14)+COUNTIF('Story Library'!$H$2:$H$300,A14) | E14: =COUNTIF('Principle Library'!$O$2:$O$300,A14) | F14: =COUNTIFS('Quote Library'!$C$2:$C$500,A14,'Quote Library'!$R$2:$R$500,"A - Primary source")+COUNTIFS('Quote Library'!$C$2:$C$500,A14,'Quote Library'!$R$2:$R$500,"B - Authoritative secondary") | G14: =COUNTIFS('Quote Library'!$C$2:$C$500,A14,'Quote Library'!$V$2:$V$500,"High") | H14: =COUNTIFS('Quote Library'!$C$2:$C$500,A14,'Quote Library'!$AD$2:$AD$500,"Released") | I14: =MAX(B14-C14,0) | J14: =MIN(C14/B14,1) | K14: =IF(J14<0.5,"High",IF(J14<0.9,"Medium","Filled"))
A15: Rest / Limits / Wellbeing | B15: 50 | C15: =COUNTIF('Quote Library'!$C$2:$C$500,A15)+COUNTIF('Quote Library'!$D$2:$D$500,A15) | D15: =COUNTIF('Story Library'!$G$2:$G$300,A15)+COUNTIF('Story Library'!$H$2:$H$300,A15) | E15: =COUNTIF('Principle Library'!$O$2:$O$300,A15) | F15: =COUNTIFS('Quote Library'!$C$2:$C$500,A15,'Quote Library'!$R$2:$R$500,"A - Primary source")+COUNTIFS('Quote Library'!$C$2:$C$500,A15,'Quote Library'!$R$2:$R$500,"B - Authoritative secondary") | G15: =COUNTIFS('Quote Library'!$C$2:$C$500,A15,'Quote Library'!$V$2:$V$500,"High") | H15: =COUNTIFS('Quote Library'!$C$2:$C$500,A15,'Quote Library'!$AD$2:$AD$500,"Released") | I15: =MAX(B15-C15,0) | J15: =MIN(C15/B15,1) | K15: =IF(J15<0.5,"High",IF(J15<0.9,"Medium","Filled"))

Sheet Dashboard
A1: SELFLO WISDOM LIBRARY — DASHBOARD
A3: Metric | B3: Value
A4: Quotes collected | B4: =COUNTIF('Quote Library'!$B$2:$B$500,"<>")
A5: Quotes verified A/B | B5: =COUNTIF('Quote Library'!$R$2:$R$500,"A - Primary source")+COUNTIF('Quote Library'!$R$2:$R$500,"B - Authoritative secondary")
A6: Quotes high Selflo fit | B6: =COUNTIF('Quote Library'!$V$2:$V$500,"High")
A7: Released quotes | B7: =COUNTIF('Quote Library'!$AD$2:$AD$500,"Released")
A8: Stories collected | B8: =COUNTIF('Story Library'!$B$2:$B$300,"<>")
A9: Stories gate passed | B9: =COUNTIF('Story Library'!$AA$2:$AA$300,"Passed")
A10: Principles collected | B10: =COUNTIF('Principle Library'!$B$2:$B$300,"<>")
A11: Sources registered | B11: =COUNTIF('Source Registry'!$A$2:$A$300,"<>")
A12: 90-day tasks done | B12: =COUNTIF('90-Day Plan'!$L$2:$L$91,"Done")
A13: 90-day progress | B13: =COUNTIF('90-Day Plan'!$L$2:$L$91,"Done")/90
A16: Cluster | B16: Quote Count | C16: Target | D16: Coverage %
A17: Exhaustion / Recovery / Work carryover | B17: ='Coverage Map'!C4 | C17: ='Coverage Map'!B4 | D17: ='Coverage Map'!J4
A18: Self-compassion / Self-blame | B18: ='Coverage Map'!C5 | C18: ='Coverage Map'!B5 | D18: ='Coverage Map'!J5
A19: Uncertainty / Choice / Agency | B19: ='Coverage Map'!C6 | C19: ='Coverage Map'!B6 | D19: ='Coverage Map'!J6
A20: Comparison / External standards / Values | B20: ='Coverage Map'!C7 | C20: ='Coverage Map'!B7 | D20: ='Coverage Map'!J7
A21: Attention / Noise / Deep focus | B21: ='Coverage Map'!C8 | C21: ='Coverage Map'!B8 | D21: ='Coverage Map'!J8
A22: Learning / Failure / Quiet growth | B22: ='Coverage Map'!C9 | C22: ='Coverage Map'!B9 | D22: ='Coverage Map'!J9
A23: Change / Impermanence / Recovery | B23: ='Coverage Map'!C10 | C23: ='Coverage Map'!B10 | D23: ='Coverage Map'!J10
A24: Mixed emotions / Emotional memory | B24: ='Coverage Map'!C11 | C24: ='Coverage Map'!B11 | D24: ='Coverage Map'!J11
A25: Meaning / Identity / Work | B25: ='Coverage Map'!C12 | C25: ='Coverage Map'!B12 | D25: ='Coverage Map'!J12
A26: AI-age Human Judgment | B26: ='Coverage Map'!C13 | C26: ='Coverage Map'!B13 | D26: ='Coverage Map'!J13
A27: Relationships / Boundaries / Connection | B27: ='Coverage Map'!C14 | C27: ='Coverage Map'!B14 | D27: ='Coverage Map'!J14
A28: Rest / Limits / Wellbeing | B28: ='Coverage Map'!C15 | C28: ='Coverage Map'!B15 | D28: ='Coverage Map'!J15

Sheet AI Collection Guide
A1: AI COLLECTION GUIDE — dùng workbook này để giao việc từng ngày
A3: Step | B3: Instruction | C3: Required Output | D3: Do Not | E3: Quality Gate | F3: Where to Save
A4: 1 | B4: Chọn Day trong 90-Day Plan. Dùng đúng Collection Focus, Sources/Traditions và What to Collect của ngày đó. | C4: Danh sách candidate + source evidence. | D4: Không tự đổi sang chủ đề khác chỉ vì dễ tìm. | E4: Ưu tiên primary/authoritative sources. | F4: 90-Day Plan
A5: 2 | B5: Thu quote/passages rộng; chưa lọc quá sớm theo Selflo fit. | C5: Original text, working VI, author/tradition, work/chapter, URL, quote type. | D5: Không dùng quote aggregator làm nguồn cuối nếu có thể truy primary. | E5: Wording và attribution phải traceable. | F5: Quote Library
A6: 3 | B6: Với proverb/folk wisdom, xác định culture/region/collection càng cụ thể càng tốt. | C6: Variant, tradition, source collection, URL. | D6: Không ghi generic 'African proverb' nếu không xác định được. | E6: Nếu provenance yếu → Verification C/D. | F6: Quote Library + Source Registry
A7: 4 | B7: Thu story/parables/cases chỉ khi có provenance. | C7: Title, summary, source work/location, URL, story type, context. | D7: Không tự bịa hoặc ghép nhiều chuyện thành một chuyện thật. | E7: Story không nguồn → không nhập như verified story. | F7: Story Library
A8: 5 | B8: Với psychology/research, lưu finding chứ không biến finding thành quote của researcher. | C8: Finding, source paper, limitation, principle seed. | D8: Không tạo fake quote từ abstract/conclusion. | E8: Phải có limitation/counterpoint nếu source hỗ trợ. | F8: Principle Library
A9: 6 | B9: Nếu external sources không phủ một human experience, có thể tạo Selflo Original seed. | C9: Label Selflo Original - AI-assisted draft + research basis. | D9: Không gán cho tác giả khác; không paraphrase tác phẩm copyrighted để né quyền. | E9: Chỉ là seed, chưa Release. | F9: Quote Library
A10: 7 | B10: Đăng ký source/tác giả/tradition mới. | C10: Source ID, title, author, language, URL, reliability tier, rights notes. | D10: Không tạo URL hoặc bibliographic detail không kiểm chứng. | E10: Tier 1/2 ưu tiên. | F10: Source Registry
A11: 8 | B11: Cập nhật Actual + Status sau khi nhập library. | C11: Quote/Story/Principle Actual, notes, status Done/In progress. | D11: Không đánh Done nếu dữ liệu chưa được nhập. | E11: Actual phải khớp số item thực nhập. | F11: 90-Day Plan
A14: Prompt mẫu giao cho AI
A15: Thực hiện [DAY X] trong workbook Selflo Wisdom Library. 1) Bám đúng Collection Focus / Primary Sources / What to Collect. 2) Internet-first, ưu tiên primary hoặc authoritative sources. 3) Thu thập rộng cho Research Pool; chưa loại chỉ vì chưa hoàn toàn Selflo-fit. 4) Mỗi quote phải có original wording nếu có, author/tradition, source title, work/chapter/location, source URL, quote type và verification grade. 5) Phân biệt verbatim / published translation / working translation / paraphrase / proverb / Selflo Original. 6) Không bịa nguồn, URL, tác giả, story hoặc provenance. Attribution không chắc phải đánh C/D. 7) Story chỉ thu nếu có nguồn rõ. Research finding không được biến thành quote. 8) Gắn cluster, human experience và editorial role sơ bộ. 9) Báo các quote bị loại vì fake attribution hoặc không truy được nguồn. 10) Trả output theo đúng cột của Quote Library, Story Library, Principle Library và Source Registry; cuối cùng báo Actual để cập nhật 90-Day Plan.
A23: QUY TẮC HOÀN THÀNH MỖI DAY
A24: Một Day = một scope nghiên cứu hoàn chỉnh, KHÔNG phải quota số lượng. Chỉ đánh Done khi audit hết phạm vi, lưu candidate đáng giữ, giữ nguyên văn/ngôn ngữ gốc cho nội dung dịch, ghi nhận story/metaphor/principle trung thực và hoàn tất provenance cơ bản. Nếu scope không có story thì ghi 0; không bịa để đạt target.

Sheet Daily Log
A1: Date | B1: Day | C1: Phase | D1: Focus | E1: Quotes Added | F1: Stories Added | G1: Principles Added | H1: Sources Added | I1: Verification A/B | J1: Rejected / Disputed | K1: Key Discoveries | L1: Coverage Gaps Found | M1: Next Action

Sheet Human Experience Map
A1: Experience ID | B1: Cluster | C1: Human Experience / Tension | D1: User-like Example | E1: Needed Editorial Job | F1: Quote Target | G1: Quote Actual | H1: Story Actual | I1: Principle Actual | J1: Coverage Status | K1: Notes
A2: EXP-001 | B2: Exhaustion / Recovery / Work carryover | C2: Nhiều việc nhỏ làm cạn năng lượng | D2: Không có việc nào quá lớn, sao mình vẫn mệt? | E2: Name / Permit | F2: 8 | G2: =COUNTIF('Quote Library'!$E$2:$E$500,C2) | H2: =COUNTIF('Story Library'!$I$2:$I$300,C2) | I2: =COUNTIF('Principle Library'!$N$2:$N$300,C2) | J2: =IF(G2=0,"Gap",IF(G2<F2,"Building","Covered"))
A3: EXP-002 | B3: Exhaustion / Recovery / Work carryover | C3: Công việc còn ở lại sau giờ làm | D3: Mình về nhà rồi nhưng đầu vẫn ở công ty. | E3: Recognize / Name | F3: 8 | G3: =COUNTIF('Quote Library'!$E$2:$E$500,C3) | H3: =COUNTIF('Story Library'!$I$2:$I$300,C3) | I3: =COUNTIF('Principle Library'!$N$2:$N$300,C3) | J3: =IF(G3=0,"Gap",IF(G3<F3,"Building","Covered"))
A4: EXP-003 | B4: Exhaustion / Recovery / Work carryover | C4: Sự kiện đã qua nhưng hồi phục chưa xong | D4: Chuyện qua rồi, sao mình vẫn chưa ổn? | E4: Recognize / Permit / Distinguish | F4: 8 | G4: =COUNTIF('Quote Library'!$E$2:$E$500,C4) | H4: =COUNTIF('Story Library'!$I$2:$I$300,C4) | I4: =COUNTIF('Principle Library'!$N$2:$N$300,C4) | J4: =IF(G4=0,"Gap",IF(G4<F4,"Building","Covered"))
A5: EXP-004 | B5: Self-compassion / Self-blame | C5: Đã gây hậu quả và đang tự trách | D5: Mình làm sai nên rất khó chịu với chính mình. | E5: Distinguish / Permit | F5: 8 | G5: =COUNTIF('Quote Library'!$E$2:$E$500,C5) | H5: =COUNTIF('Story Library'!$I$2:$I$300,C5) | I5: =COUNTIF('Principle Library'!$N$2:$N$300,C5) | J5: =IF(G5=0,"Gap",IF(G5<F5,"Building","Covered"))
A6: EXP-005 | B6: Self-compassion / Self-blame | C6: Đang học nhưng thấy mình kém | D6: Mình còn vụng; có phải mình không đủ tốt? | E6: Reframe / Permit | F6: 8 | G6: =COUNTIF('Quote Library'!$E$2:$E$500,C6) | H6: =COUNTIF('Story Library'!$I$2:$I$300,C6) | I6: =COUNTIF('Principle Library'!$N$2:$N$300,C6) | J6: =IF(G6=0,"Gap",IF(G6<F6,"Building","Covered"))
A7: EXP-006 | B7: Uncertainty / Choice / Agency | C7: Chưa biết và chưa cần quyết định ngay | D7: Mình vẫn chưa biết mình muốn gì. | E7: Permit / Return agency | F7: 8 | G7: =COUNTIF('Quote Library'!$E$2:$E$500,C7) | H7: =COUNTIF('Story Library'!$I$2:$I$300,C7) | I7: =COUNTIF('Principle Library'!$N$2:$N$300,C7) | J7: =IF(G7=0,"Gap",IF(G7<F7,"Building","Covered"))
A8: EXP-007 | B8: Uncertainty / Choice / Agency | C8: Quá nhiều câu trả lời | D8: Càng hỏi thêm mình càng khó chọn. | E8: Distinguish / Return agency | F8: 8 | G8: =COUNTIF('Quote Library'!$E$2:$E$500,C8) | H8: =COUNTIF('Story Library'!$I$2:$I$300,C8) | I8: =COUNTIF('Principle Library'!$N$2:$N$300,C8) | J8: =IF(G8=0,"Gap",IF(G8<F8,"Building","Covered"))
A9: EXP-008 | B9: Uncertainty / Choice / Agency | C9: Hai lựa chọn đều có điều đáng giữ | D9: Ở lại có cái mất; đi cũng có cái mất. | E9: Recognize / Permit | F9: 8 | G9: =COUNTIF('Quote Library'!$E$2:$E$500,C9) | H9: =COUNTIF('Story Library'!$I$2:$I$300,C9) | I9: =COUNTIF('Principle Library'!$N$2:$N$300,C9) | J9: =IF(G9=0,"Gap",IF(G9<F9,"Building","Covered"))
A10: EXP-009 | B10: Comparison / External standards / Values | C10: Thành công của người khác làm mình thấy nhỏ đi | D10: Người khác tiến lên còn mình đứng yên. | E10: Reframe | F10: 8 | G10: =COUNTIF('Quote Library'!$E$2:$E$500,C10) | H10: =COUNTIF('Story Library'!$I$2:$I$300,C10) | I10: =COUNTIF('Principle Library'!$N$2:$N$300,C10) | J10: =IF(G10=0,"Gap",IF(G10<F10,"Building","Covered"))
A11: EXP-010 | B11: Comparison / External standards / Values | C11: Sống bằng thước đo bên ngoài | D11: Mình đang dùng tiêu chuẩn của ai để đánh giá đời mình? | E11: Distinguish / Return agency | F11: 8 | G11: =COUNTIF('Quote Library'!$E$2:$E$500,C11) | H11: =COUNTIF('Story Library'!$I$2:$I$300,C11) | I11: =COUNTIF('Principle Library'!$N$2:$N$300,C11) | J11: =IF(G11=0,"Gap",IF(G11<F11,"Building","Covered"))
A12: EXP-011 | B12: Attention / Noise / Deep focus | C12: Tiếp nhận nhiều nhưng không nghe được mình | D12: Cả ngày có quá nhiều tiếng nói. | E12: Recognize / Distinguish | F12: 8 | G12: =COUNTIF('Quote Library'!$E$2:$E$500,C12) | H12: =COUNTIF('Story Library'!$I$2:$I$300,C12) | I12: =COUNTIF('Principle Library'!$N$2:$N$300,C12) | J12: =IF(G12=0,"Gap",IF(G12<F12,"Building","Covered"))
A13: EXP-012 | B13: Learning / Failure / Quiet growth | C13: Tiến bộ âm thầm | D13: Mình không thấy mình tiến bộ gì. | E13: Recognize / Reframe | F13: 8 | G13: =COUNTIF('Quote Library'!$E$2:$E$500,C13) | H13: =COUNTIF('Story Library'!$I$2:$I$300,C13) | I13: =COUNTIF('Principle Library'!$N$2:$N$300,C13) | J13: =IF(G13=0,"Gap",IF(G13<F13,"Building","Covered"))
... A17: EXP-016 | B17: AI-age Human Judgment | C17: Nhiều output nhưng judgment vẫn là của mình | D17: Có rất nhiều câu trả lời, nhưng câu nào thật sự là của mình? | E17: Distinguish / Return agency | F17: 8 | G17: =COUNTIF('Quote Library'!$E$2:$E$500,C17) | H17: =COUNTIF('Story Library'!$I$2:$I$300,C17) | I17: =COUNTIF('Principle Library'!$N$2:$N$300,C17) | J17: =IF(G17=0,"Gap",IF(G17<F17,"Building","Covered"))

Sheet Taxonomy VN
A1: SELFLO TAXONOMY — HƯỚNG DẪN PHÂN LOẠI & COVERAGE
A3: Tầng | B3: Tên taxonomy | C3: Câu hỏi taxonomy trả lời | D3: Ví dụ | E3: Dùng để đánh giá coverage | F3: Ghi chú
A4: 1 | B4: Lĩnh vực cuộc sống (Life Area) | C4: Người dùng đang ở vùng nào của đời sống? | D4: Công việc; Nội tâm; Quan hệ; Gia đình; Nghỉ ngơi | E4: Độ rộng các vùng đời sống | F4: Không dùng Life Area thay cho trải nghiệm cụ thể.
A5: 2 | B5: Trải nghiệm con người (Human Experience) | C5: Điều gì cụ thể đang xảy ra với người dùng? | D5: Công việc vẫn ở trong đầu sau giờ làm | E5: Đây là đơn vị coverage QUAN TRỌNG NHẤT | F5: Một Life Area có nhiều Human Experience.
A6: 3 | B6: Chủ đề (Theme) | C6: Những ý tưởng nào đang được chạm tới? | D6: Recovery; Attention; Boundaries | E6: Độ rộng ý niệm | F6: Một Experience có thể có nhiều Theme.
A7: 4 | B7: Cảm xúc / trạng thái (Emotion / State) | C7: Người dùng có thể đang cảm thấy/trải qua trạng thái gì? | D7: Mệt; lo; bối rối; tiếc nuối; nhẹ nhõm | E7: Coverage theo trạng thái cảm xúc | F7: Không chẩn đoán người dùng; đây là tag biên tập.
A8: 5 | B8: Vai trò biên tập (Editorial Role) | C8: Nội dung đang làm gì cho người đọc? | D8: Recognize; Name; Permit; Reframe; Distinguish; Return agency | E8: Độ đa dạng góc nhìn trong cùng Experience | F8: Tránh library chỉ toàn Reframe/inspiration.
A9: 6 | B9: Hình thức nội dung (Content Form) | C9: Câu được thể hiện bằng cách nào? | D9: Quan sát; ẩn dụ; câu hỏi; nghịch lý; tục ngữ; thơ | E9: Độ đa dạng giọng và hình thức | F9: Tránh 1.000 câu nhưng đều cùng kiểu viết.
A10: 7 | B10: Nguyên lý nền (Principle) | C10: Research/triết lý nào đứng phía sau? | D10: Psychological detachment; mixed emotions; human agency | E10: Độ sâu tri thức | F10: Principle thường không cần hiện trực tiếp với user.
A11: 8 | B11: Nguồn / truyền thống (Source / Tradition) | C11: Nội dung đến từ đâu? | D11: Đạo gia; Stoicism; Việt Nam; Literature; Psychology | E11: Độ đa dạng văn hóa/tác giả/nguồn | F11: Theo dõi over-representation.
A12: 9 | B12: Mức xác minh (Verification) | C12: Attribution/source đáng tin tới đâu? | D12: A primary; B authoritative; C needs primary; D disputed | E12: Chất lượng provenance | F12: D vẫn có thể giữ research nhưng không tự động Release.
A13: 10 | B13: Quyền sử dụng (Rights) | C13: Có thể dùng nội dung như thế nào? | D13: Public domain; copyrighted; permission needed | E13: Khả năng sử dụng thực tế | F13: Tách quality khỏi rights.
A14: 11 | B14: Mức phù hợp Selflo (Selflo Fit) | C14: Nội dung có hợp triết lý Selflo không? | D14: High / Medium / Low / Not reviewed | E14: Chỉ dùng ở phase curate | F14: Không lọc quá sớm trong giai đoạn Collect.
A17: COVERAGE NGHĨA LÀ GÌ?
A18: Mức | B18: Ý nghĩa | C18: Quy tắc gợi ý | D18: Ví dụ | E18: Hành động
A19: 🔴 Missing | B19: Chưa có nội dung cho trải nghiệm. | C19: 0 quote phù hợp. | D19: Mixed emotions: 0 | E19: Ưu tiên collect.
A20: 🟠 Thin | B20: Có nội dung nhưng góc nhìn còn mỏng. | C20: 1–2 quote hoặc chỉ 1 editorial role. | D20: Chỉ có Reframe. | E20: Tìm thêm nguồn/góc nhìn khác.
A21: 🟡 Covered | B21: Đã có nhiều góc nhìn đủ dùng. | C21: ≥3 quote và ≥2 editorial roles, nguồn không quá lệch. | D21: Recognize + Permit + Distinguish. | E21: Không cần ép thêm số lượng.
A22: 🟢 Rich | B22: Coverage giàu và đa dạng. | C22: Nhiều editorial roles + source/form diversity + story/principle khi hữu ích. | D22: Quote + story + research + nhiều truyền thống. | E22: Chỉ bổ sung khi có giá trị mới.
A25: VÍ DỤ PHÂN LOẠI MỘT QUOTE
A26: Quote | B26: Mưa đã tạnh. Mặt đất chưa khô. Nhưng mưa đã tạnh.
A27: Life Area | B27: Nội tâm & cảm xúc
A28: Human Experience | B28: Chuyện đã qua nhưng mình chưa hồi phục
A29: Theme | B29: Recovery; Impermanence
A30: Emotion / State | B30: Lingering emotion; mệt; buồn (tag biên tập, không chẩn đoán)
A31: Editorial Role | B31: Recognize + Permit
A32: Content Form | B32: Ẩn dụ (Metaphor)
A33: Source | B33: Selflo Original
A34: Selflo Fit | B34: High

Sheet Quote Library v2
A1: Quote ID | B1: Trạng thái | C1: Lĩnh vực cuộc sống (Life Area) | D1: Cluster chính | E1: Cluster phụ | F1: Trải nghiệm con người (Human Experience) | G1: Chủ đề chính (Theme) | H1: Chủ đề phụ | I1: Cảm xúc / trạng thái chính | J1: Cảm xúc / trạng thái phụ | K1: Vai trò biên tập chính | L1: Vai trò biên tập phụ | M1: Hình thức nội dung (Content Form) | N1: Nguyên văn | O1: Ngôn ngữ | P1: Bản dịch / bản làm việc tiếng Việt | Q1: Tác giả / Attribution | R1: Truyền thống / khu vực | S1: Tên nguồn / tác phẩm | T1: Chương / vị trí | U1: Source URL | V1: Loại nguồn | W1: Loại quote | X1: Mức xác minh | Y1: Ghi chú xác minh | Z1: Quyền sử dụng | AA1: Ghi chú copyright / usage | AB1: Mức phù hợp Selflo | AC1: Ghi chú Selflo Fit | AD1: Rủi ro giáo điều / directive | AE1: Rủi ro trùng ý | AF1: Principle ID liên quan | AG1: Story ID liên quan | AH1: Story dependency gate | AI1: Owner review | AJ1: Release readiness | AK1: Vị trí library hiện tại | AL1: Ngày trong plan | AM1: Người thu thập | AN1: Ngày thu thập | AO1: Ghi chú
A2: research.laozi.ch01.001 | B2: Collected | C2: Ý nghĩa & bản sắc | D2: AI-age Human Judgment | F2: Tên gọi không bao giờ chứa trọn điều được gọi | G2: Judgment | H2: Uncertainty | I2: Không chắc chắn | K2: Distinguish | L2: Recognize | M2: Trích đoạn triết học | N2: 道可道，非常道；名可名，非常名。 | O2: Classical Chinese (文言文) | P2: Đạo có thể nói thành lời thì không phải Đạo thường hằng; tên có thể gọi thành tên thì không phải tên thường hằng. | Q2: Laozi / 老子 | R2: Taoism | S2: 道德經 / Tao Te Ching | T2: Chapter 1 | U2: https://zh.wikisource.org/zh-hans/%E9%81%93%E5%BE%B7%E7%B6%93_(%E7%8E%8B%E5%BC%BC%E6%9C%AC) | V2: Primary text | W2: Working translation | X2: A - Primary source | Y2: Original Chinese checked against Wang Bi recension; cross-check via Chinese Text Project. Vietnamese is Selflo working translation, not published translation. | Z2: Public domain / likely | AA2: Ancient text; Legge 1891 comparison is public domain in USA per Project Gutenberg. Verify jurisdiction for commercial publication. | AB2: High | AC2: Mạnh cho distinction: mô tả/nhãn ≠ toàn bộ thực tại. | AD2: Needs editorial review | AE2: Needs semantic dedupe review | AH2: No | AI2: Not reviewed | AJ2: Research only | AK2: Research Pool | AL2: 1 | AM2: ChatGPT research | AN2: 2026-09-18 | AO2: Day 1 full-scope audit, chapters 1–20.
A3: research.laozi.ch01.002 | B3: Collected | C3: Ý nghĩa & bản sắc | D3: Change / Impermanence / Recovery | F3: Tên gọi làm kinh nghiệm trở nên có hình | G3: Identity | H3: Meaning | I3: Không gọi tên được | K3: Name | L3: Distinguish | M3: Trích đoạn triết học | N3: 無名，天地之始；有名，萬物之母。 | O3: Classical Chinese (文言文) | P3: Không tên là khởi đầu của trời đất; có tên là mẹ của muôn vật. | Q3: Laozi / 老子 | R3: Taoism | S3: 道德經 / Tao Te Ching | T3: Chapter 1 | U3: https://zh.wikisource.org/zh-hans/%E9%81%93%E5%BE%B7%E7%B6%93_(%E7%8E%8B%E5%BC%BC%E6%9C%AC) | V3: Primary text | W3: Working translation | X3: A - Primary source | Y3: Original Chinese checked against Wang Bi recension; cross-check via Chinese Text Project. Vietnamese is Selflo working translation, not published translation. | Z3: Public domain / likely | AA3: Ancient text; Legge 1891 comparison is public domain in USA per Project Gutenberg. Verify jurisdiction for commercial publication. | AB3: Medium | AC3: Giữ research pool; ý siêu hình, cần ngữ cảnh nếu public. | AD3: Needs editorial review | AE3: Needs semantic dedupe review | AH3: No | AI3: Not reviewed | AJ3: Research only | AK3: Research Pool | AL3: 1 | AM3: ChatGPT research | AN3: 2026-09-18 | AO3: Day 1 full-scope audit, chapters 1–20.
A4: research.laozi.ch01.003 | B4: Collected | C4: Nội tâm & hiểu mình | D4: Attention / Noise / Deep focus | F4: Ham muốn có thể làm thay đổi cách mình nhìn một điều | G4: Attention | H4: Judgment | I4: Áp lực | K4: Recognize | L4: Distinguish | M4: Trích đoạn triết học | N4: 故常無欲，以觀其妙；常有欲，以觀其徼。 | O4: Classical Chinese (文言文) | P4: Khi không bị dục vọng kéo đi, ta có thể nhìn phần vi diệu; khi có ham muốn, ta thường nhìn phần biểu hiện và giới hạn của sự vật. | Q4: Laozi / 老子 | R4: Taoism | S4: 道德經 / Tao Te Ching | T4: Chapter 1 | U4: https://zh.wikisource.org/zh-hans/%E9%81%93%E5%BE%B7%E7%B6%93_(%E7%8E%8B%E5%BC%BC%E6%9C%AC) | V4: Primary text | W4: Working translation | X4: A - Primary source | Y4: Original Chinese checked against Wang Bi recension; cross-check via Chinese Text Project. Vietnamese is Selflo working translation, not published translation. | Z4: Public domain / likely | AA4: Ancient text; Legge 1891 comparison is public domain in USA per Project Gutenberg. Verify jurisdiction for commercial publication. | AB4: Medium | AC4: Working translation diễn giải; cần review học thuật. | AD4: Needs editorial review | AE4: Needs semantic dedupe review | AH4: No | AI4: Not reviewed | AJ4: Research only | AK4: Research Pool | AL4: 1 | AM4: ChatGPT research | AN4: 2026-09-18 | AO4: Day 1 full-scope audit, chapters 1–20.
A5: research.laozi.ch01.004 | B5: Collected | C5: Nội tâm & hiểu mình | D5: Mixed emotions / Emotional memory | F5: Hai mặt khác nhau có thể cùng thuộc một thực tại | G5: Change | H5: Acceptance | I5: Mixed / contradictory | K5: Distinguish | L5: Permit | M5: Trích đoạn triết học | N5: 此兩者，同出而異名，同謂之玄。 | O5: Classical Chinese (文言文) | P5: Hai mặt ấy cùng đi ra từ một nguồn, chỉ mang những tên khác nhau. | Q5: Laozi / 老子 | R5: Taoism | S5: 道德經 / Tao Te Ching | T5: Chapter 1 | U5: https://zh.wikisource.org/zh-hans/%E9%81%93%E5%BE%B7%E7%B6%93_(%E7%8E%8B%E5%BC%BC%E6%9C%AC) | V5: Primary text | W5: Working translation | X5: A - Primary source | Y5: Original Chinese checked against Wang Bi recension; cross-check via Chinese Text Project. Vietnamese is Selflo working translation, not published translation. | Z5: Public domain / likely | AA5: Ancient text; Legge 1891 comparison is public domain in USA per Project Gutenberg. Verify jurisdiction for commercial publication. | AB5: High | AC5: Gần triết lý hai mặt/đối cực của Selflo. | AD5: Needs editorial review | AE5: Needs semantic dedupe review | AH5: No | AI5: Not reviewed | AJ5: Research only | AK5: Research Pool | AL5: 1 | AM5: ChatGPT research | AN5: 2026-09-18 | AO5: Day 1 full-scope audit, chapters 1–20.
A6: research.laozi.ch02.005 | B6: Collected | C6: Xã hội & văn hóa | D6: Comparison / External standards / Values | F6: Một tiêu chuẩn tạo ra cả phía được chọn và phía bị loại | G6: Comparison | H6: Judgment | I6: Áp lực | K6: Distinguish | L6: Recognize | M6: Trích đoạn triết học | N6: 天下皆知美之為美，斯惡已；皆知善之為善，斯不善已。 | O6: Classical Chinese (文言文) | P6: Khi mọi người nhận ra cái đẹp là đẹp, ý niệm về cái không đẹp cũng xuất hiện; khi gọi điều này là tốt, điều không tốt cũng được phân biệt. | Q6: Laozi / 老子 | R6: Taoism | S6: 道德經 / Tao Te Ching | T6: Chapter 2 | U6: https://zh.wikisource.org/zh-hans/%E9%81%93%E5%BE%B7%E7%B6%93_(%E7%8E%8B%E5%BC%BC%E6%9C%AC) | V6: Primary text | W6: Working translation | X6: A - Primary source | Y6: Original Chinese checked against Wang Bi recension; cross-check via Chinese Text Project. Vietnamese is Selflo working translation, not published translation. | Z6: Public domain / likely | AA6: Ancient text; Legge 1891 comparison is public domain in USA per Project Gutenberg. Verify jurisdiction for commercial publication. | AB6: High | AC6: Hữu ích cho standards/comparison; tránh biến thành phủ nhận thiện-ác. | AD6: Needs editorial review | AE6: Needs semantic dedupe review | AH6: No | AI6: Not reviewed | AJ6: Research only | AK6: Research Pool | AL6: 1 | AM6: ChatGPT research | AN6: 2026-09-18 | AO6: Day 1 full-scope audit, chapters 1–20.
A7: research.laozi.ch02.006 | B7: Collected | C7: Nội tâm & hiểu mình | D7: Mixed emotions / Emotional memory | F7: Những mặt đối lập có thể định nghĩa và làm rõ nhau | G7: Change | H7: Acceptance | I7: Mixed / contradictory | K7: Distinguish | L7: Reframe | M7: Trích đoạn triết học | N7: 有無相生，難易相成，長短相較，高下相傾，音聲相和，前後相隨。 | O7: Classical Chinese (文言文) | P7: Có và không sinh ra nhau; khó và dễ thành tựu lẫn nhau; dài và ngắn làm rõ nhau; cao và thấp dựa vào nhau; âm và tiếng hòa cùng nhau; trước và sau nối tiếp nhau. | Q7: Laozi / 老子 | R7: Taoism | S7: 道德經 / Tao Te Ching | T7: Chapter 2 | U7: https://zh.wikisource.org/zh-hans/%E9%81%93%E5%BE%B7%E7%B6%93_(%E7%8E%8B%E5%BC%BC%E6%9C%AC) | V7: Primary text | W7: Working translation | X7: A - Primary source | Y7: Original Chinese checked against Wang Bi recension; cross-check via Chinese Text Project. Vietnamese is Selflo working translation, not published translation. | Z7: Public domain / likely | AA7: Ancient text; Legge 1891 comparison is public domain in USA per Project Gutenberg. Verify jurisdiction for commercial publication. | AB7: High | AC7: Một trong các candidate mạnh nhất Day 1. | AD7: Needs editorial review | AE7: Needs semantic dedupe review | AH7: No | AI7: Not reviewed | AJ7: Research only | AK7: Research Pool | AL7: 1 | AM7: ChatGPT research | AN7: 2026-09-18 | AO7: Day 1 full-scope audit, chapters 1–20.
A8: research.laozi.ch02.007 | B8: Collected | C8: Quan hệ | D8: Relationships / Boundaries / Connection | F8: Chăm sóc hoặc tạo ra điều gì đó mà không biến nó thành sở hữu | G8: Agency | H8: Connection | I8: Bình yên | K8: Reframe | L8: Distinguish | M8: Trích đoạn triết học | N8: 萬物作焉而不辭，生而不有，為而不恃。 | O8: Classical Chinese (文言文) | P8: Muôn vật sinh khởi mà không bị giữ lại; sinh ra mà không chiếm hữu, làm mà không cậy vào việc mình đã làm. | Q8: Laozi / 老子 | R8: Taoism | S8: 道德經 / Tao Te Ching | T8: Chapter 2 | U8: https://zh.wikisource.org/zh-hans/%E9%81%93%E5%BE%B7%E7%B6%93_(%E7%8E%8B%E5%BC%BC%E6%9C%AC) | V8: Primary text | W8: Working translation | X8: A - Primary source | Y8: Original Chinese checked against Wang Bi recension; cross-check via Chinese Text Project. Vietnamese is Selflo working translation, not published translation. | Z8: Public domain / likely | AA8: Ancient text; Legge 1891 comparison is public domain in USA per Project Gutenberg. Verify jurisdiction for commercial publication. | AB8: Medium | AC8: Có thể hữu ích cho parenting/leadership; cần ngữ cảnh. | AD8: Needs editorial review | AE8: Needs semantic dedupe review | AH8: No | AI8: Not reviewed | AJ8: Research only | AK8: Research Pool | AL8: 1 | AM8: ChatGPT research | AN8: 2026-09-18 | AO8: Day 1 full-scope audit, chapters 1–20.
